Workbook

Sheet Setup
A1: IFMS assisted due–drawn workbook
A2: Template version | B2: ifms-assisted-worksheet-v1
A3: Employee Name
A4: Employee Code
A5: Kind | B5: hra
A6: Rounding | B6: rupee
A7: Template Id | B7: jodhpur_classic
A8: Include Hda | B8: No
A10: Fill blue cells. The supplied statement updates automatically in Excel.
A11: Return this workbook to the app to recheck its literal inputs and export PDF.
A12: DRAFT: rates, entitlement and payment history need office verification.

Sheet Monthly inputs
A1: MONTHLY INPUTS — blue cells are editable; blanks are unresolved
A2: Drawn and due values are full-month amounts. Dates prorate them. Earlier paid amounts and extra deductions are actual allocations; never prorated again.
A3: Do not repeat previous payments already included in Drawn. One effective change per month; use manual monthly amounts for blended changes.
A5: month | B5: start | C5: end | D5: presentation | E5: drawn_BASIC | F5: drawn_DA | G5: drawn_HRA | H5: drawn_HDA | I5: drawn_CCA | J5: new_basic | K5: da_rate | L5: hra_rate | M5: hda_divisor | N5: due_BASIC | O5: due_DA | P5: due_HRA | Q5: due_HDA | R5: due_CCA | S5: prior_BASIC | T5: prior_DA | U5: prior_HRA | V5: prior_HDA | W5: prior_CCA | X5: ded_GPF | Y5: ded_SI | Z5: ded_CM_CORONA | AA5: ded_I_TAX | AB5: ded_GPF_TO_DEDUCT | AC5: ded_GPF_ALREADY_DEDUCTED | AD5: ded_SIF_ALREADY_DEDUCTED | AE5: salary_reference | AF5: order_reference | AG5: history_reference | AH5: deduction_reference | AI5: history_reviewed | AJ5: deductions_reviewed | AK5: bill_no | AL5: bill_date | AM5: tv_no | AN5: tv_date | AO5: ledger_payment_id | AP5: ledger_snapshot | AQ5: INPUT CHECK
A6: 2026-01 | B6: 46023 | C6: 46053 | D6: period | AQ6: =IF(COUNTA('Monthly inputs'!A6:AP6)=0,"UNUSED",IFERROR(IF(AND(AND(COUNT('Monthly inputs'!E6,'Monthly inputs'!F6,'Monthly inputs'!G6,'Monthly inputs'!H6,'Monthly inputs'!I6,'Monthly inputs'!S6,'Monthly inputs'!T6,'Monthly inputs'!U6,'Monthly inputs'!V6,'Monthly inputs'!W6)=10,MIN('Monthly inputs'!E6,'Monthly inputs'!F6,'Monthly inputs'!G6,'Monthly inputs'!H6,'Monthly inputs'!I6,'Monthly inputs'!S6,'Monthly inputs'!T6,'Monthly inputs'!U6,'Monthly inputs'!V6,'Monthly inputs'!W6)>=0,MAX('Monthly inputs'!E6,'Monthly inputs'!F6,'Monthly inputs'!G6,'Monthly inputs'!H6,'Monthly inputs'!I6,'Monthly inputs'!S6,'Monthly inputs'!T6,'Monthly inputs'!U6,'Monthly inputs'!V6,'Monthly inputs'!W6)<=100000000,'Monthly inputs'!E6=ROUND('Monthly inputs'!E6,2),'Monthly inputs'!F6=ROUND('Monthly inputs'!F6,2),'Monthly inputs'!G6=ROUND('Monthly inputs'!G6,2),'Monthly inputs'!H6=ROUND('Monthly inputs'!H6,2),'Monthly inputs'!I6=ROUND('Monthly inputs'!I6,2),'Monthly inputs'!S6=ROUND('Monthly inputs'!S6,2),'Monthly inputs'!T6=ROUND('Monthly inputs'!T6,2),'Monthly inputs'!U6=ROUND('Monthly inputs'!U6,2),'Monthly inputs'!V6=ROUND('Monthly inputs'!V6,2),'Monthly inputs'!W6=ROUND('Monthly inputs'!W6,2)),ISNUMBER('Monthly inputs'!B6),ISNUMBER('Monthly inputs'!C6),'Monthly inputs'!B6<='Monthly inputs'!C6,TEXT('Monthly inputs'!B6,"yyyy-mm")='Monthly inputs'!A6,TEXT('Monthly inputs'!C6,"yyyy-mm")='Monthly inputs'!A6,OR('Monthly inputs'!D6="period",'Monthly inputs'!D6="whole_month"),LEN(TRIM('Monthly inputs'!AE6))>0,LEN(TRIM('Monthly inputs'!AF6))>0,LEN(TRIM('Monthly inputs'!AG6))>0,LEN(TRIM('Monthly inputs'!AH6))>0,'Monthly inputs'!AI6="Yes",'Monthly inputs'!AJ6="Yes",LEN(TRIM(Setup!B3))>0,LEN(TRIM(Setup!B4))>0,OR(Setup!B6="rupee",Setup!B6="paise"),OR(Setup!B8="Yes",Setup!B8="No"),IF(Setup!B5="manual",AND(COUNT('Monthly inputs'!N6,'Monthly inputs'!O6,'Monthly inputs'!P6,'Monthly inputs'!Q6,'Monthly inputs'!R6)=5,MIN('Monthly inputs'!N6,'Monthly inputs'!O6,'Monthly inputs'!P6,'Monthly inputs'!Q6,'Monthly inputs'!R6)>=0,MAX('Monthly inputs'!N6,'Monthly inputs'!O6,'Monthly inputs'!P6,'Monthly inputs'!Q6,'Monthly inputs'!R6)<=100000000,'Monthly inputs'!N6=ROUND('Monthly inputs'!N6,2),'Monthly inputs'!O6=ROUND('Monthly inputs'!O6,2),'Monthly inputs'!P6=ROUND('Monthly inputs'!P6,2),'Monthly inputs'!Q6=ROUND('Monthly inputs'!Q6,2),'Monthly inputs'!R6=ROUND('Monthly inputs'!R6,2)),IF(Setup!B5="increment",AND(COUNT('Monthly inputs'!J6,'Monthly inputs'!K6,'Monthly inputs'!L6)=3,MIN('Monthly inputs'!J6,'Monthly inputs'!K6,'Monthly inputs'!L6)>=0,MAX('Monthly inputs'!J6,'Monthly inputs'!K6,'Monthly inputs'!L6)<=100000000,'Monthly inputs'!J6=ROUND('Monthly inputs'!J6,2),'Monthly inputs'!K6<=1000,'Monthly inputs'!L6<=1000),IF(Setup!B5="da",AND(COUNT('Monthly inputs'!K6)=1,MIN('Monthly inputs'!K6)>=0,MAX('Monthly inputs'!K6)<=100000000,'Monthly inputs'!K6<=1000),IF(Setup!B5="hra",AND(COUNT('Monthly inputs'!L6)=1,MIN('Monthly inputs'!L6)>=0,MAX('Monthly inputs'!L6)<=100000000,'Monthly inputs'!L6<=1000),FALSE)))),IF(AND(OR(Setup!B5="increment",Setup!B5="da"),Setup!B8="Yes"),AND(COUNT('Monthly inputs'!M6)=1,MIN('Monthly inputs'!M6)>=0,MAX('Monthly inputs'!M6)<=100000000,'Monthly inputs'!M6>0),TRUE),IF(Setup!B7="jodhpur_gpf_arrear",AND(AND(COUNT('Monthly inputs'!AB6,'Monthly inputs'!AC6,'Monthly inputs'!AD6,'Monthly inputs'!AA6)=4,MIN('Monthly inputs'!AB6,'Monthly inputs'!AC6,'Monthly inputs'!AD6,'Monthly inputs'!AA6)>=0,MAX('Monthly inputs'!AB6,'Monthly inputs'!AC6,'Monthly inputs'!AD6,'Monthly inputs'!AA6)<=100000000,'Monthly inputs'!AB6=ROUND('Monthly inputs'!AB6,2),'Monthly inputs'!AC6=ROUND('Monthly inputs'!AC6,2),'Monthly inputs'!AD6=ROUND('Monthly inputs'!AD6,2),'Monthly inputs'!AA6=ROUND('Monthly inputs'!AA6,2)),OR('Monthly inputs'!X6="",'Monthly inputs'!X6=0),OR('Monthly inputs'!Y6="",'Monthly inputs'!Y6=0),OR('Monthly inputs'!Z6="",'Monthly inputs'!Z6=0)),IF(Setup!B7="jodhpur_classic",AND(AND(COUNT('Monthly inputs'!X6,'Monthly inputs'!Y6,'Monthly inputs'!Z6,'Monthly inputs'!AA6)=4,MIN('Monthly inputs'!X6,'Monthly inputs'!Y6,'Monthly inputs'!Z6,'Monthly inputs'!AA6)>=0,MAX('Monthly inputs'!X6,'Monthly inputs'!Y6,'Monthly inputs'!Z6,'Monthly inputs'!AA6)<=100000000,'Monthly inputs'!X6=ROUND('Monthly inputs'!X6,2),'Monthly inputs'!Y6=ROUND('Monthly inputs'!Y6,2),'Monthly inputs'!Z6=ROUND('Monthly inputs'!Z6,2),'Monthly inputs'!AA6=ROUND('Monthly inputs'!AA6,2)),OR('Monthly inputs'!AB6="",'Monthly inputs'!AB6=0),OR('Monthly inputs'!AC6="",'Monthly inputs'!AC6=0),OR('Monthly inputs'!AD6="",'Monthly inputs'!AD6=0)),FALSE))),"OK","INCOMPLETE"),"INCOMPLETE"))
A7: 2026-02 | B7: 46054 | C7: 46081 | D7: period | AQ7: =IF(COUNTA('Monthly inputs'!A7:AP7)=0,"UNUSED",IFERROR(IF(AND(AND(COUNT('Monthly inputs'!E7,'Monthly inputs'!F7,'Monthly inputs'!G7,'Monthly inputs'!H7,'Monthly inputs'!I7,'Monthly inputs'!S7,'Monthly inputs'!T7,'Monthly inputs'!U7,'Monthly inputs'!V7,'Monthly inputs'!W7)=10,MIN('Monthly inputs'!E7,'Monthly inputs'!F7,'Monthly inputs'!G7,'Monthly inputs'!H7,'Monthly inputs'!I7,'Monthly inputs'!S7,'Monthly inputs'!T7,'Monthly inputs'!U7,'Monthly inputs'!V7,'Monthly inputs'!W7)>=0,MAX('Monthly inputs'!E7,'Monthly inputs'!F7,'Monthly inputs'!G7,'Monthly inputs'!H7,'Monthly inputs'!I7,'Monthly inputs'!S7,'Monthly inputs'!T7,'Monthly inputs'!U7,'Monthly inputs'!V7,'Monthly inputs'!W7)<=100000000,'Monthly inputs'!E7=ROUND('Monthly inputs'!E7,2),'Monthly inputs'!F7=ROUND('Monthly inputs'!F7,2),'Monthly inputs'!G7=ROUND('Monthly inputs'!G7,2),'Monthly inputs'!H7=ROUND('Monthly inputs'!H7,2),'Monthly inputs'!I7=ROUND('Monthly inputs'!I7,2),'Monthly inputs'!S7=ROUND('Monthly inputs'!S7,2),'Monthly inputs'!T7=ROUND('Monthly inputs'!T7,2),'Monthly inputs'!U7=ROUND('Monthly inputs'!U7,2),'Monthly inputs'!V7=ROUND('Monthly inputs'!V7,2),'Monthly inputs'!W7=ROUND('Monthly inputs'!W7,2)),ISNUMBER('Monthly inputs'!B7),ISNUMBER('Monthly inputs'!C7),'Monthly inputs'!B7<='Monthly inputs'!C7,TEXT('Monthly inputs'!B7,"yyyy-mm")='Monthly inputs'!A7,TEXT('Monthly inputs'!C7,"yyyy-mm")='Monthly inputs'!A7,OR('Monthly inputs'!D7="period",'Monthly inputs'!D7="whole_month"),'Monthly inputs'!B7='Monthly inputs'!C6+1,'Monthly inputs'!A7<>'Monthly inputs'!A6,LEN(TRIM('Monthly inputs'!AE7))>0,LEN(TRIM('Monthly inputs'!AF7))>0,LEN(TRIM('Monthly inputs'!AG7))>0,LEN(TRIM('Monthly inputs'!AH7))>0,'Monthly inputs'!AI7="Yes",'Monthly inputs'!AJ7="Yes",LEN(TRIM(Setup!B3))>0,LEN(TRIM(Setup!B4))>0,OR(Setup!B6="rupee",Setup!B6="paise"),OR(Setup!B8="Yes",Setup!B8="No"),IF(Setup!B5="manual",AND(COUNT('Monthly inputs'!N7,'Monthly inputs'!O7,'Monthly inputs'!P7,'Monthly inputs'!Q7,'Monthly inputs'!R7)=5,MIN('Monthly inputs'!N7,'Monthly inputs'!O7,'Monthly inputs'!P7,'Monthly inputs'!Q7,'Monthly inputs'!R7)>=0,MAX('Monthly inputs'!N7,'Monthly inputs'!O7,'Monthly inputs'!P7,'Monthly inputs'!Q7,'Monthly inputs'!R7)<=100000000,'Monthly inputs'!N7=ROUND('Monthly inputs'!N7,2),'Monthly inputs'!O7=ROUND('Monthly inputs'!O7,2),'Monthly inputs'!P7=ROUND('Monthly inputs'!P7,2),'Monthly inputs'!Q7=ROUND('Monthly inputs'!Q7,2),'Monthly inputs'!R7=ROUND('Monthly inputs'!R7,2)),IF(Setup!B5="increment",AND(COUNT('Monthly inputs'!J7,'Monthly inputs'!K7,'Monthly inputs'!L7)=3,MIN('Monthly inputs'!J7,'Monthly inputs'!K7,'Monthly inputs'!L7)>=0,MAX('Monthly inputs'!J7,'Monthly inputs'!K7,'Monthly inputs'!L7)<=100000000,'Monthly inputs'!J7=ROUND('Monthly inputs'!J7,2),'Monthly inputs'!K7<=1000,'Monthly inputs'!L7<=1000),IF(Setup!B5="da",AND(COUNT('Monthly inputs'!K7)=1,MIN('Monthly inputs'!K7)>=0,MAX('Monthly inputs'!K7)<=100000000,'Monthly inputs'!K7<=1000),IF(Setup!B5="hra",AND(COUNT('Monthly inputs'!L7)=1,MIN('Monthly inputs'!L7)>=0,MAX('Monthly inputs'!L7)<=100000000,'Monthly inputs'!L7<=1000),FALSE)))),IF(AND(OR(Setup!B5="increment",Setup!B5="da"),Setup!B8="Yes"),AND(COUNT('Monthly inputs'!M7)=1,MIN('Monthly inputs'!M7)>=0,MAX('Monthly inputs'!M7)<=100000000,'Monthly inputs'!M7>0),TRUE),IF(Setup!B7="jodhpur_gpf_arrear",AND(AND(COUNT('Monthly inputs'!AB7,'Monthly inputs'!AC7,'Monthly inputs'!AD7,'Monthly inputs'!AA7)=4,MIN('Monthly inputs'!AB7,'Monthly inputs'!AC7,'Monthly inputs'!AD7,'Monthly inputs'!AA7)>=0,MAX('Monthly inputs'!AB7,'Monthly inputs'!AC7,'Monthly inputs'!AD7,'Monthly inputs'!AA7)<=100000000,'Monthly inputs'!AB7=ROUND('Monthly inputs'!AB7,2),'Monthly inputs'!AC7=ROUND('Monthly inputs'!AC7,2),'Monthly inputs'!AD7=ROUND('Monthly inputs'!AD7,2),'Monthly inputs'!AA7=ROUND('Monthly inputs'!AA7,2)),OR('Monthly inputs'!X7="",'Monthly inputs'!X7=0),OR('Monthly inputs'!Y7="",'Monthly inputs'!Y7=0),OR('Monthly inputs'!Z7="",'Monthly inputs'!Z7=0)),IF(Setup!B7="jodhpur_classic",AND(AND(COUNT('Monthly inputs'!X7,'Monthly inputs'!Y7,'Monthly inputs'!Z7,'Monthly inputs'!AA7)=4,MIN('Monthly inputs'!X7,'Monthly inputs'!Y7,'Monthly inputs'!Z7,'Monthly inputs'!AA7)>=0,MAX('Monthly inputs'!X7,'Monthly inputs'!Y7,'Monthly inputs'!Z7,'Monthly inputs'!AA7)<=100000000,'Monthly inputs'!X7=ROUND('Monthly inputs'!X7,2),'Monthly inputs'!Y7=ROUND('Monthly inputs'!Y7,2),'Monthly inputs'!Z7=ROUND('Monthly inputs'!Z7,2),'Monthly inputs'!AA7=ROUND('Monthly inputs'!AA7,2)),OR('Monthly inputs'!AB7="",'Monthly inputs'!AB7=0),OR('Monthly inputs'!AC7="",'Monthly inputs'!AC7=0),OR('Monthly inputs'!AD7="",'Monthly inputs'!AD7=0)),FALSE))),"OK","INCOMPLETE"),"INCOMPLETE"))
A8: 2026-03 | B8: 46082 | C8: 46112 | D8: period | AQ8: =IF(COUNTA('Monthly inputs'!A8:AP8)=0,"UNUSED",IFERROR(IF(AND(AND(COUNT('Monthly inputs'!E8,'Monthly inputs'!F8,'Monthly inputs'!G8,'Monthly inputs'!H8,'Monthly inputs'!I8,'Monthly inputs'!S8,'Monthly inputs'!T8,'Monthly inputs'!U8,'Monthly inputs'!V8,'Monthly inputs'!W8)=10,MIN('Monthly inputs'!E8,'Monthly inputs'!F8,'Monthly inputs'!G8,'Monthly inputs'!H8,'Monthly inputs'!I8,'Monthly inputs'!S8,'Monthly inputs'!T8,'Monthly inputs'!U8,'Monthly inputs'!V8,'Monthly inputs'!W8)>=0,MAX('Monthly inputs'!E8,'Monthly inputs'!F8,'Monthly inputs'!G8,'Monthly inputs'!H8,'Monthly inputs'!I8,'Monthly inputs'!S8,'Monthly inputs'!T8,'Monthly inputs'!U8,'Monthly inputs'!V8,'Monthly inputs'!W8)<=100000000,'Monthly inputs'!E8=ROUND('Monthly inputs'!E8,2),'Monthly inputs'!F8=ROUND('Monthly inputs'!F8,2),'Monthly inputs'!G8=ROUND('Monthly inputs'!G8,2),'Monthly inputs'!H8=ROUND('Monthly inputs'!H8,2),'Monthly inputs'!I8=ROUND('Monthly inputs'!I8,2),'Monthly inputs'!S8=ROUND('Monthly inputs'!S8,2),'Monthly inputs'!T8=ROUND('Monthly inputs'!T8,2),'Monthly inputs'!U8=ROUND('Monthly inputs'!U8,2),'Monthly inputs'!V8=ROUND('Monthly inputs'!V8,2),'Monthly inputs'!W8=ROUND('Monthly inputs'!W8,2)),ISNUMBER('Monthly inputs'!B8),ISNUMBER('Monthly inputs'!C8),'Monthly inputs'!B8<='Monthly inputs'!C8,TEXT('Monthly inputs'!B8,"yyyy-mm")='Monthly inputs'!A8,TEXT('Monthly inputs'!C8,"yyyy-mm")='Monthly inputs'!A8,OR('Monthly inputs'!D8="period",'Monthly inputs'!D8="whole_month"),'Monthly inputs'!B8='Monthly inputs'!C7+1,'Monthly inputs'!A8<>'Monthly inputs'!A7,LEN(TRIM('Monthly inputs'!AE8))>0,LEN(TRIM('Monthly inputs'!AF8))>0,LEN(TRIM('Monthly inputs'!AG8))>0,LEN(TRIM('Monthly inputs'!AH8))>0,'Monthly inputs'!AI8="Yes",'Monthly inputs'!AJ8="Yes",LEN(TRIM(Setup!B3))>0,LEN(TRIM(Setup!B4))>0,OR(Setup!B6="rupee",Setup!B6="paise"),OR(Setup!B8="Yes",Setup!B8="No"),IF(Setup!B5="manual",AND(COUNT('Monthly inputs'!N8,'Monthly inputs'!O8,'Monthly inputs'!P8,'Monthly inputs'!Q8,'Monthly inputs'!R8)=5,MIN('Monthly inputs'!N8,'Monthly inputs'!O8,'Monthly inputs'!P8,'Monthly inputs'!Q8,'Monthly inputs'!R8)>=0,MAX('Monthly inputs'!N8,'Monthly inputs'!O8,'Monthly inputs'!P8,'Monthly inputs'!Q8,'Monthly inputs'!R8)<=100000000,'Monthly inputs'!N8=ROUND('Monthly inputs'!N8,2),'Monthly inputs'!O8=ROUND('Monthly inputs'!O8,2),'Monthly inputs'!P8=ROUND('Monthly inputs'!P8,2),'Monthly inputs'!Q8=ROUND('Monthly inputs'!Q8,2),'Monthly inputs'!R8=ROUND('Monthly inputs'!R8,2)),IF(Setup!B5="increment",AND(COUNT('Monthly inputs'!J8,'Monthly inputs'!K8,'Monthly inputs'!L8)=3,MIN('Monthly inputs'!J8,'Monthly inputs'!K8,'Monthly inputs'!L8)>=0,MAX('Monthly inputs'!J8,'Monthly inputs'!K8,'Monthly inputs'!L8)<=100000000,'Monthly inputs'!J8=ROUND('Monthly inputs'!J8,2),'Monthly inputs'!K8<=1000,'Monthly inputs'!L8<=1000),IF(Setup!B5="da",AND(COUNT('Monthly inputs'!K8)=1,MIN('Monthly inputs'!K8)>=0,MAX('Monthly inputs'!K8)<=100000000,'Monthly inputs'!K8<=1000),IF(Setup!B5="hra",AND(COUNT('Monthly inputs'!L8)=1,MIN('Monthly inputs'!L8)>=0,MAX('Monthly inputs'!L8)<=100000000,'Monthly inputs'!L8<=1000),FALSE)))),IF(AND(OR(Setup!B5="increment",Setup!B5="da"),Setup!B8="Yes"),AND(COUNT('Monthly inputs'!M8)=1,MIN('Monthly inputs'!M8)>=0,MAX('Monthly inputs'!M8)<=100000000,'Monthly inputs'!M8>0),TRUE),IF(Setup!B7="jodhpur_gpf_arrear",AND(AND(COUNT('Monthly inputs'!AB8,'Monthly inputs'!AC8,'Monthly inputs'!AD8,'Monthly inputs'!AA8)=4,MIN('Monthly inputs'!AB8,'Monthly inputs'!AC8,'Monthly inputs'!AD8,'Monthly inputs'!AA8)>=0,MAX('Monthly inputs'!AB8,'Monthly inputs'!AC8,'Monthly inputs'!AD8,'Monthly inputs'!AA8)<=100000000,'Monthly inputs'!AB8=ROUND('Monthly inputs'!AB8,2),'Monthly inputs'!AC8=ROUND('Monthly inputs'!AC8,2),'Monthly inputs'!AD8=ROUND('Monthly inputs'!AD8,2),'Monthly inputs'!AA8=ROUND('Monthly inputs'!AA8,2)),OR('Monthly inputs'!X8="",'Monthly inputs'!X8=0),OR('Monthly inputs'!Y8="",'Monthly inputs'!Y8=0),OR('Monthly inputs'!Z8="",'Monthly inputs'!Z8=0)),IF(Setup!B7="jodhpur_classic",AND(AND(COUNT('Monthly inputs'!X8,'Monthly inputs'!Y8,'Monthly inputs'!Z8,'Monthly inputs'!AA8)=4,MIN('Monthly inputs'!X8,'Monthly inputs'!Y8,'Monthly inputs'!Z8,'Monthly inputs'!AA8)>=0,MAX('Monthly inputs'!X8,'Monthly inputs'!Y8,'Monthly inputs'!Z8,'Monthly inputs'!AA8)<=100000000,'Monthly inputs'!X8=ROUND('Monthly inputs'!X8,2),'Monthly inputs'!Y8=ROUND('Monthly inputs'!Y8,2),'Monthly inputs'!Z8=ROUND('Monthly inputs'!Z8,2),'Monthly inputs'!AA8=ROUND('Monthly inputs'!AA8,2)),OR('Monthly inputs'!AB8="",'Monthly inputs'!AB8=0),OR('Monthly inputs'!AC8="",'Monthly inputs'!AC8=0),OR('Monthly inputs'!AD8="",'Monthly inputs'!AD8=0)),FALSE))),"OK","INCOMPLETE"),"INCOMPLETE"))
A9: 2026-04 | B9: 46113 | C9: 46142 | D9: period | AQ9: =IF(COUNTA('Monthly inputs'!A9:AP9)=0,"UNUSED",IFERROR(IF(AND(AND(COUNT('Monthly inputs'!E9,'Monthly inputs'!F9,'Monthly inputs'!G9,'Monthly inputs'!H9,'Monthly inputs'!I9,'Monthly inputs'!S9,'Monthly inputs'!T9,'Monthly inputs'!U9,'Monthly inputs'!V9,'Monthly inputs'!W9)=10,MIN('Monthly inputs'!E9,'Monthly inputs'!F9,'Monthly inputs'!G9,'Monthly inputs'!H9,'Monthly inputs'!I9,'Monthly inputs'!S9,'Monthly inputs'!T9,'Monthly inputs'!U9,'Monthly inputs'!V9,'Monthly inputs'!W9)>=0,MAX('Monthly inputs'!E9,'Monthly inputs'!F9,'Monthly inputs'!G9,'Monthly inputs'!H9,'Monthly inputs'!I9,'Monthly inputs'!S9,'Monthly inputs'!T9,'Monthly inputs'!U9,'Monthly inputs'!V9,'Monthly inputs'!W9)<=100000000,'Monthly inputs'!E9=ROUND('Monthly inputs'!E9,2),'Monthly inputs'!F9=ROUND('Monthly inputs'!F9,2),'Monthly inputs'!G9=ROUND('Monthly inputs'!G9,2),'Monthly inputs'!H9=ROUND('Monthly inputs'!H9,2),'Monthly inputs'!I9=ROUND('Monthly inputs'!I9,2),'Monthly inputs'!S9=ROUND('Monthly inputs'!S9,2),'Monthly inputs'!T9=ROUND('Monthly inputs'!T9,2),'Monthly inputs'!U9=ROUND('Monthly inputs'!U9,2),'Monthly inputs'!V9=ROUND('Monthly inputs'!V9,2),'Monthly inputs'!W9=ROUND('Monthly inputs'!W9,2)),ISNUMBER('Monthly inputs'!B9),ISNUMBER('Monthly inputs'!C9),'Monthly inputs'!B9<='Monthly inputs'!C9,TEXT('Monthly inputs'!B9,"yyyy-mm")='Monthly inputs'!A9,TEXT('Monthly inputs'!C9,"yyyy-mm")='Monthly inputs'!A9,OR('Monthly inputs'!D9="period",'Monthly inputs'!D9="whole_month"),'Monthly inputs'!B9='Monthly inputs'!C8+1,'Monthly inputs'!A9<>'Monthly inputs'!A8,LEN(TRIM('Monthly inputs'!AE9))>0,LEN(TRIM('Monthly inputs'!AF9))>0,LEN(TRIM('Monthly inputs'!AG9))>0,LEN(TRIM('Monthly inputs'!AH9))>0,'Monthly inputs'!AI9="Yes",'Monthly inputs'!AJ9="Yes",LEN(TRIM(Setup!B3))>0,LEN(TRIM(Setup!B4))>0,OR(Setup!B6="rupee",Setup!B6="paise"),OR(Setup!B8="Yes",Setup!B8="No"),IF(Setup!B5="manual",AND(COUNT('Monthly inputs'!N9,'Monthly inputs'!O9,'Monthly inputs'!P9,'Monthly inputs'!Q9,'Monthly inputs'!R9)=5,MIN('Monthly inputs'!N9,'Monthly inputs'!O9,'Monthly inputs'!P9,'Monthly inputs'!Q9,'Monthly inputs'!R9)>=0,MAX('Monthly inputs'!N9,'Monthly inputs'!O9,'Monthly inputs'!P9,'Monthly inputs'!Q9,'Monthly inputs'!R9)<=100000000,'Monthly inputs'!N9=ROUND('Monthly inputs'!N9,2),'Monthly inputs'!O9=ROUND('Monthly inputs'!O9,2),'Monthly inputs'!P9=ROUND('Monthly inputs'!P9,2),'Monthly inputs'!Q9=ROUND('Monthly inputs'!Q9,2),'Monthly inputs'!R9=ROUND('Monthly inputs'!R9,2)),IF(Setup!B5="increment",AND(COUNT('Monthly inputs'!J9,'Monthly inputs'!K9,'Monthly inputs'!L9)=3,MIN('Monthly inputs'!J9,'Monthly inputs'!K9,'Monthly inputs'!L9)>=0,MAX('Monthly inputs'!J9,'Monthly inputs'!K9,'Monthly inputs'!L9)<=100000000,'Monthly inputs'!J9=ROUND('Monthly inputs'!J9,2),'Monthly inputs'!K9<=1000,'Monthly inputs'!L9<=1000),IF(Setup!B5="da",AND(COUNT('Monthly inputs'!K9)=1,MIN('Monthly inputs'!K9)>=0,MAX('Monthly inputs'!K9)<=100000000,'Monthly inputs'!K9<=1000),IF(Setup!B5="hra",AND(COUNT('Monthly inputs'!L9)=1,MIN('Monthly inputs'!L9)>=0,MAX('Monthly inputs'!L9)<=100000000,'Monthly inputs'!L9<=1000),FALSE)))),IF(AND(OR(Setup!B5="increment",Setup!B5="da"),Setup!B8="Yes"),AND(COUNT('Monthly inputs'!M9)=1,MIN('Monthly inputs'!M9)>=0,MAX('Monthly inputs'!M9)<=100000000,'Monthly inputs'!M9>0),TRUE),IF(Setup!B7="jodhpur_gpf_arrear",AND(AND(COUNT('Monthly inputs'!AB9,'Monthly inputs'!AC9,'Monthly inputs'!AD9,'Monthly inputs'!AA9)=4,MIN('Monthly inputs'!AB9,'Monthly inputs'!AC9,'Monthly inputs'!AD9,'Monthly inputs'!AA9)>=0,MAX('Monthly inputs'!AB9,'Monthly inputs'!AC9,'Monthly inputs'!AD9,'Monthly inputs'!AA9)<=100000000,'Monthly inputs'!AB9=ROUND('Monthly inputs'!AB9,2),'Monthly inputs'!AC9=ROUND('Monthly inputs'!AC9,2),'Monthly inputs'!AD9=ROUND('Monthly inputs'!AD9,2),'Monthly inputs'!AA9=ROUND('Monthly inputs'!AA9,2)),OR('Monthly inputs'!X9="",'Monthly inputs'!X9=0),OR('Monthly inputs'!Y9="",'Monthly inputs'!Y9=0),OR('Monthly inputs'!Z9="",'Monthly inputs'!Z9=0)),IF(Setup!B7="jodhpur_classic",AND(AND(COUNT('Monthly inputs'!X9,'Monthly inputs'!Y9,'Monthly inputs'!Z9,'Monthly inputs'!AA9)=4,MIN('Monthly inputs'!X9,'Monthly inputs'!Y9,'Monthly inputs'!Z9,'Monthly inputs'!AA9)>=0,MAX('Monthly inputs'!X9,'Monthly inputs'!Y9,'Monthly inputs'!Z9,'Monthly inputs'!AA9)<=100000000,'Monthly inputs'!X9=ROUND('Monthly inputs'!X9,2),'Monthly inputs'!Y9=ROUND('Monthly inputs'!Y9,2),'Monthly inputs'!Z9=ROUND('Monthly inputs'!Z9,2),'Monthly inputs'!AA9=ROUND('Monthly inputs'!AA9,2)),OR('Monthly inputs'!AB9="",'Monthly inputs'!AB9=0),OR('Monthly inputs'!AC9="",'Monthly inputs'!AC9=0),OR('Monthly inputs'!AD9="",'Monthly inputs'!AD9=0)),FALSE))),"OK","INCOMPLETE"),"INCOMPLETE"))
A10: 2026-05 | B10: 46143 | C10: 46173 | D10: period | AQ10: =IF(COUNTA('Monthly inputs'!A10:AP10)=0,"UNUSED",IFERROR(IF(AND(AND(COUNT('Monthly inputs'!E10,'Monthly inputs'!F10,'Monthly inputs'!G10,'Monthly inputs'!H10,'Monthly inputs'!I10,'Monthly inputs'!S10,'Monthly inputs'!T10,'Monthly inputs'!U10,'Monthly inputs'!V10,'Monthly inputs'!W10)=10,MIN('Monthly inputs'!E10,'Monthly inputs'!F10,'Monthly inputs'!G10,'Monthly inputs'!H10,'Monthly inputs'!I10,'Monthly inputs'!S10,'Monthly inputs'!T10,'Monthly inputs'!U10,'Monthly inputs'!V10,'Monthly inputs'!W10)>=0,MAX('Monthly inputs'!E10,'Monthly inputs'!F10,'Monthly inputs'!G10,'Monthly inputs'!H10,'Monthly inputs'!I10,'Monthly inputs'!S10,'Monthly inputs'!T10,'Monthly inputs'!U10,'Monthly inputs'!V10,'Monthly inputs'!W10)<=100000000,'Monthly inputs'!E10=ROUND('Monthly inputs'!E10,2),'Monthly inputs'!F10=ROUND('Monthly inputs'!F10,2),'Monthly inputs'!G10=ROUND('Monthly inputs'!G10,2),'Monthly inputs'!H10=ROUND('Monthly inputs'!H10,2),'Monthly inputs'!I10=ROUND('Monthly inputs'!I10,2),'Monthly inputs'!S10=ROUND('Monthly inputs'!S10,2),'Monthly inputs'!T10=ROUND('Monthly inputs'!T10,2),'Monthly inputs'!U10=ROUND('Monthly inputs'!U10,2),'Monthly inputs'!V10=ROUND('Monthly inputs'!V10,2),'Monthly inputs'!W10=ROUND('Monthly inputs'!W10,2)),ISNUMBER('Monthly inputs'!B10),ISNUMBER('Monthly inputs'!C10),'Monthly inputs'!B10<='Monthly inputs'!C10,TEXT('Monthly inputs'!B10,"yyyy-mm")='Monthly inputs'!A10,TEXT('Monthly inputs'!C10,"yyyy-mm")='Monthly inputs'!A10,OR('Monthly inputs'!D10="period",'Monthly inputs'!D10="whole_month"),'Monthly inputs'!B10='Monthly inputs'!C9+1,'Monthly inputs'!A10<>'Monthly inputs'!A9,LEN(TRIM('Monthly inputs'!AE10))>0,LEN(TRIM('Monthly inputs'!AF10))>0,LEN(TRIM('Monthly inputs'!AG10))>0,LEN(TRIM('Monthly inputs'!AH10))>0,'Monthly inputs'!AI10="Yes",'Monthly inputs'!AJ10="Yes",LEN(TRIM(Setup!B3))>0,LEN(TRIM(Setup!B4))>0,OR(Setup!B6="rupee",Setup!B6="paise"),OR(Setup!B8="Yes",Setup!B8="No"),IF(Setup!B5="manual",AND(COUNT('Monthly inputs'!N10,'Monthly inputs'!O10,'Monthly inputs'!P10,'Monthly inputs'!Q10,'Monthly inputs'!R10)=5,MIN('Monthly inputs'!N10,'Monthly inputs'!O10,'Monthly inputs'!P10,'Monthly inputs'!Q10,'Monthly inputs'!R10)>=0,MAX('Monthly inputs'!N10,'Monthly inputs'!O10,'Monthly inputs'!P10,'Monthly inputs'!Q10,'Monthly inputs'!R10)<=100000000,'Monthly inputs'!N10=ROUND('Monthly inputs'!N10,2),'Monthly inputs'!O10=ROUND('Monthly inputs'!O10,2),'Monthly inputs'!P10=ROUND('Monthly inputs'!P10,2),'Monthly inputs'!Q10=ROUND('Monthly inputs'!Q10,2),'Monthly inputs'!R10=ROUND('Monthly inputs'!R10,2)),IF(Setup!B5="increment",AND(COUNT('Monthly inputs'!J10,'Monthly inputs'!K10,'Monthly inputs'!L10)=3,MIN('Monthly inputs'!J10,'Monthly inputs'!K10,'Monthly inputs'!L10)>=0,MAX('Monthly inputs'!J10,'Monthly inputs'!K10,'Monthly inputs'!L10)<=100000000,'Monthly inputs'!J10=ROUND('Monthly inputs'!J10,2),'Monthly inputs'!K10<=1000,'Monthly inputs'!L10<=1000),IF(Setup!B5="da",AND(COUNT('Monthly inputs'!K10)=1,MIN('Monthly inputs'!K10)>=0,MAX('Monthly inputs'!K10)<=100000000,'Monthly inputs'!K10<=1000),IF(Setup!B5="hra",AND(COUNT('Monthly inputs'!L10)=1,MIN('Monthly inputs'!L10)>=0,MAX('Monthly inputs'!L10)<=100000000,'Monthly inputs'!L10<=1000),FALSE)))),IF(AND(OR(Setup!B5="increment",Setup!B5="da"),Setup!B8="Yes"),AND(COUNT('Monthly inputs'!M10)=1,MIN('Monthly inputs'!M10)>=0,MAX('Monthly inputs'!M10)<=100000000,'Monthly inputs'!M10>0),TRUE),IF(Setup!B7="jodhpur_gpf_arrear",AND(AND(COUNT('Monthly inputs'!AB10,'Monthly inputs'!AC10,'Monthly inputs'!AD10,'Monthly inputs'!AA10)=4,MIN('Monthly inputs'!AB10,'Monthly inputs'!AC10,'Monthly inputs'!AD10,'Monthly inputs'!AA10)>=0,MAX('Monthly inputs'!AB10,'Monthly inputs'!AC10,'Monthly inputs'!AD10,'Monthly inputs'!AA10)<=100000000,'Monthly inputs'!AB10=ROUND('Monthly inputs'!AB10,2),'Monthly inputs'!AC10=ROUND('Monthly inputs'!AC10,2),'Monthly inputs'!AD10=ROUND('Monthly inputs'!AD10,2),'Monthly inputs'!AA10=ROUND('Monthly inputs'!AA10,2)),OR('Monthly inputs'!X10="",'Monthly inputs'!X10=0),OR('Monthly inputs'!Y10="",'Monthly inputs'!Y10=0),OR('Monthly inputs'!Z10="",'Monthly inputs'!Z10=0)),IF(Setup!B7="jodhpur_classic",AND(AND(COUNT('Monthly inputs'!X10,'Monthly inputs'!Y10,'Monthly inputs'!Z10,'Monthly inputs'!AA10)=4,MIN('Monthly inputs'!X10,'Monthly inputs'!Y10,'Monthly inputs'!Z10,'Monthly inputs'!AA10)>=0,MAX('Monthly inputs'!X10,'Monthly inputs'!Y10,'Monthly inputs'!Z10,'Monthly inputs'!AA10)<=100000000,'Monthly inputs'!X10=ROUND('Monthly inputs'!X10,2),'Monthly inputs'!Y10=ROUND('Monthly inputs'!Y10,2),'Monthly inputs'!Z10=ROUND('Monthly inputs'!Z10,2),'Monthly inputs'!AA10=ROUND('Monthly inputs'!AA10,2)),OR('Monthly inputs'!AB10="",'Monthly inputs'!AB10=0),OR('Monthly inputs'!AC10="",'Monthly inputs'!AC10=0),OR('Monthly inputs'!AD10="",'Monthly inputs'!AD10=0)),FALSE))),"OK","INCOMPLETE"),"INCOMPLETE"))
A11: 2026-06 | B11: 46174 | C11: 46203 | D11: period | AQ11: =IF(COUNTA('Monthly inputs'!A11:AP11)=0,"UNUSED",IFERROR(IF(AND(AND(COUNT('Monthly inputs'!E11,'Monthly inputs'!F11,'Monthly inputs'!G11,'Monthly inputs'!H11,'Monthly inputs'!I11,'Monthly inputs'!S11,'Monthly inputs'!T11,'Monthly inputs'!U11,'Monthly inputs'!V11,'Monthly inputs'!W11)=10,MIN('Monthly inputs'!E11,'Monthly inputs'!F11,'Monthly inputs'!G11,'Monthly inputs'!H11,'Monthly inputs'!I11,'Monthly inputs'!S11,'Monthly inputs'!T11,'Monthly inputs'!U11,'Monthly inputs'!V11,'Monthly inputs'!W11)>=0,MAX('Monthly inputs'!E11,'Monthly inputs'!F11,'Monthly inputs'!G11,'Monthly inputs'!H11,'Monthly inputs'!I11,'Monthly inputs'!S11,'Monthly inputs'!T11,'Monthly inputs'!U11,'Monthly inputs'!V11,'Monthly inputs'!W11)<=100000000,'Monthly inputs'!E11=ROUND('Monthly inputs'!E11,2),'Monthly inputs'!F11=ROUND('Monthly inputs'!F11,2),'Monthly inputs'!G11=ROUND('Monthly inputs'!G11,2),'Monthly inputs'!H11=ROUND('Monthly inputs'!H11,2),'Monthly inputs'!I11=ROUND('Monthly inputs'!I11,2),'Monthly inputs'!S11=ROUND('Monthly inputs'!S11,2),'Monthly inputs'!T11=ROUND('Monthly inputs'!T11,2),'Monthly inputs'!U11=ROUND('Monthly inputs'!U11,2),'Monthly inputs'!V11=ROUND('Monthly inputs'!V11,2),'Monthly inputs'!W11=ROUND('Monthly inputs'!W11,2)),ISNUMBER('Monthly inputs'!B11),ISNUMBER('Monthly inputs'!C11),'Monthly inputs'!B11<='Monthly inputs'!C11,TEXT('Monthly inputs'!B11,"yyyy-mm")='Monthly inputs'!A11,TEXT('Monthly inputs'!C11,"yyyy-mm")='Monthly inputs'!A11,OR('Monthly inputs'!D11="period",'Monthly inputs'!D11="whole_month"),'Monthly inputs'!B11='Monthly inputs'!C10+1,'Monthly inputs'!A11<>'Monthly inputs'!A10,LEN(TRIM('Monthly inputs'!AE11))>0,LEN(TRIM('Monthly inputs'!AF11))>0,LEN(TRIM('Monthly inputs'!AG11))>0,LEN(TRIM('Monthly inputs'!AH11))>0,'Monthly inputs'!AI11="Yes",'Monthly inputs'!AJ11="Yes",LEN(TRIM(Setup!B3))>0,LEN(TRIM(Setup!B4))>0,OR(Setup!B6="rupee",Setup!B6="paise"),OR(Setup!B8="Yes",Setup!B8="No"),IF(Setup!B5="manual",AND(COUNT('Monthly inputs'!N11,'Monthly inputs'!O11,'Monthly inputs'!P11,'Monthly inputs'!Q11,'Monthly inputs'!R11)=5,MIN('Monthly inputs'!N11,'Monthly inputs'!O11,'Monthly inputs'!P11,'Monthly inputs'!Q11,'Monthly inputs'!R11)>=0,MAX('Monthly inputs'!N11,'Monthly inputs'!O11,'Monthly inputs'!P11,'Monthly inputs'!Q11,'Monthly inputs'!R11)<=100000000,'Monthly inputs'!N11=ROUND('Monthly inputs'!N11,2),'Monthly inputs'!O11=ROUND('Monthly inputs'!O11,2),'Monthly inputs'!P11=ROUND('Monthly inputs'!P11,2),'Monthly inputs'!Q11=ROUND('Monthly inputs'!Q11,2),'Monthly inputs'!R11=ROUND('Monthly inputs'!R11,2)),IF(Setup!B5="increment",AND(COUNT('Monthly inputs'!J11,'Monthly inputs'!K11,'Monthly inputs'!L11)=3,MIN('Monthly inputs'!J11,'Monthly inputs'!K11,'Monthly inputs'!L11)>=0,MAX('Monthly inputs'!J11,'Monthly inputs'!K11,'Monthly inputs'!L11)<=100000000,'Monthly inputs'!J11=ROUND('Monthly inputs'!J11,2),'Monthly inputs'!K11<=1000,'Monthly inputs'!L11<=1000),IF(Setup!B5="da",AND(COUNT('Monthly inputs'!K11)=1,MIN('Monthly inputs'!K11)>=0,MAX('Monthly inputs'!K11)<=100000000,'Monthly inputs'!K11<=1000),IF(Setup!B5="hra",AND(COUNT('Monthly inputs'!L11)=1,MIN('Monthly inputs'!L11)>=0,MAX('Monthly inputs'!L11)<=100000000,'Monthly inputs'!L11<=1000),FALSE)))),IF(AND(OR(Setup!B5="increment",Setup!B5="da"),Setup!B8="Yes"),AND(COUNT('Monthly inputs'!M11)=1,MIN('Monthly inputs'!M11)>=0,MAX('Monthly inputs'!M11)<=100000000,'Monthly inputs'!M11>0),TRUE),IF(Setup!B7="jodhpur_gpf_arrear",AND(AND(COUNT('Monthly inputs'!AB11,'Monthly inputs'!AC11,'Monthly inputs'!AD11,'Monthly inputs'!AA11)=4,MIN('Monthly inputs'!AB11,'Monthly inputs'!AC11,'Monthly inputs'!AD11,'Monthly inputs'!AA11)>=0,MAX('Monthly inputs'!AB11,'Monthly inputs'!AC11,'Monthly inputs'!AD11,'Monthly inputs'!AA11)<=100000000,'Monthly inputs'!AB11=ROUND('Monthly inputs'!AB11,2),'Monthly inputs'!AC11=ROUND('Monthly inputs'!AC11,2),'Monthly inputs'!AD11=ROUND('Monthly inputs'!AD11,2),'Monthly inputs'!AA11=ROUND('Monthly inputs'!AA11,2)),OR('Monthly inputs'!X11="",'Monthly inputs'!X11=0),OR('Monthly inputs'!Y11="",'Monthly inputs'!Y11=0),OR('Monthly inputs'!Z11="",'Monthly inputs'!Z11=0)),IF(Setup!B7="jodhpur_classic",AND(AND(COUNT('Monthly inputs'!X11,'Monthly inputs'!Y11,'Monthly inputs'!Z11,'Monthly inputs'!AA11)=4,MIN('Monthly inputs'!X11,'Monthly inputs'!Y11,'Monthly inputs'!Z11,'Monthly inputs'!AA11)>=0,MAX('Monthly inputs'!X11,'Monthly inputs'!Y11,'Monthly inputs'!Z11,'Monthly inputs'!AA11)<=100000000,'Monthly inputs'!X11=ROUND('Monthly inputs'!X11,2),'Monthly inputs'!Y11=ROUND('Monthly inputs'!Y11,2),'Monthly inputs'!Z11=ROUND('Monthly inputs'!Z11,2),'Monthly inputs'!AA11=ROUND('Monthly inputs'!AA11,2)),OR('Monthly inputs'!AB11="",'Monthly inputs'!AB11=0),OR('Monthly inputs'!AC11="",'Monthly inputs'!AC11=0),OR('Monthly inputs'!AD11="",'Monthly inputs'!AD11=0)),FALSE))),"OK","INCOMPLETE"),"INCOMPLETE"))
A12: 2026-07 | B12: 46204 | C12: 46234 | D12: period | AQ12: =IF(COUNTA('Monthly inputs'!A12:AP12)=0,"UNUSED",IFERROR(IF(AND(AND(COUNT('Monthly inputs'!E12,'Monthly inputs'!F12,'Monthly inputs'!G12,'Monthly inputs'!H12,'Monthly inputs'!I12,'Monthly inputs'!S12,'Monthly inputs'!T12,'Monthly inputs'!U12,'Monthly inputs'!V12,'Monthly inputs'!W12)=10,MIN('Monthly inputs'!E12,'Monthly inputs'!F12,'Monthly inputs'!G12,'Monthly inputs'!H12,'Monthly inputs'!I12,'Monthly inputs'!S12,'Monthly inputs'!T12,'Monthly inputs'!U12,'Monthly inputs'!V12,'Monthly inputs'!W12)>=0,MAX('Monthly inputs'!E12,'Monthly inputs'!F12,'Monthly inputs'!G12,'Monthly inputs'!H12,'Monthly inputs'!I12,'Monthly inputs'!S12,'Monthly inputs'!T12,'Monthly inputs'!U12,'Monthly inputs'!V12,'Monthly inputs'!W12)<=100000000,'Monthly inputs'!E12=ROUND('Monthly inputs'!E12,2),'Monthly inputs'!F12=ROUND('Monthly inputs'!F12,2),'Monthly inputs'!G12=ROUND('Monthly inputs'!G12,2),'Monthly inputs'!H12=ROUND('Monthly inputs'!H12,2),'Monthly inputs'!I12=ROUND('Monthly inputs'!I12,2),'Monthly inputs'!S12=ROUND('Monthly inputs'!S12,2),'Monthly inputs'!T12=ROUND('Monthly inputs'!T12,2),'Monthly inputs'!U12=ROUND('Monthly inputs'!U12,2),'Monthly inputs'!V12=ROUND('Monthly inputs'!V12,2),'Monthly inputs'!W12=ROUND('Monthly inputs'!W12,2)),ISNUMBER('Monthly inputs'!B12),ISNUMBER('Monthly inputs'!C12),'Monthly inputs'!B12<='Monthly inputs'!C12,TEXT('Monthly inputs'!B12,"yyyy-mm")='Monthly inputs'!A12,TEXT('Monthly inputs'!C12,"yyyy-mm")='Monthly inputs'!A12,OR('Monthly inputs'!D12="period",'Monthly inputs'!D12="whole_month"),'Monthly inputs'!B12='Monthly inputs'!C11+1,'Monthly inputs'!A12<>'Monthly inputs'!A11,LEN(TRIM('Monthly inputs'!AE12))>0,LEN(TRIM('Monthly inputs'!AF12))>0,LEN(TRIM('Monthly inputs'!AG12))>0,LEN(TRIM('Monthly inputs'!AH12))>0,'Monthly inputs'!AI12="Yes",'Monthly inputs'!AJ12="Yes",LEN(TRIM(Setup!B3))>0,LEN(TRIM(Setup!B4))>0,OR(Setup!B6="rupee",Setup!B6="paise"),OR(Setup!B8="Yes",Setup!B8="No"),IF(Setup!B5="manual",AND(COUNT('Monthly inputs'!N12,'Monthly inputs'!O12,'Monthly inputs'!P12,'Monthly inputs'!Q12,'Monthly inputs'!R12)=5,MIN('Monthly inputs'!N12,'Monthly inputs'!O12,'Monthly inputs'!P12,'Monthly inputs'!Q12,'Monthly inputs'!R12)>=0,MAX('Monthly inputs'!N12,'Monthly inputs'!O12,'Monthly inputs'!P12,'Monthly inputs'!Q12,'Monthly inputs'!R12)<=100000000,'Monthly inputs'!N12=ROUND('Monthly inputs'!N12,2),'Monthly inputs'!O12=ROUND('Monthly inputs'!O12,2),'Monthly inputs'!P12=ROUND('Monthly inputs'!P12,2),'Monthly inputs'!Q12=ROUND('Monthly inputs'!Q12,2),'Monthly inputs'!R12=ROUND('Monthly inputs'!R12,2)),IF(Setup!B5="increment",AND(COUNT('Monthly inputs'!J12,'Monthly inputs'!K12,'Monthly inputs'!L12)=3,MIN('Monthly inputs'!J12,'Monthly inputs'!K12,'Monthly inputs'!L12)>=0,MAX('Monthly inputs'!J12,'Monthly inputs'!K12,'Monthly inputs'!L12)<=100000000,'Monthly inputs'!J12=ROUND('Monthly inputs'!J12,2),'Monthly inputs'!K12<=1000,'Monthly inputs'!L12<=1000),IF(Setup!B5="da",AND(COUNT('Monthly inputs'!K12)=1,MIN('Monthly inputs'!K12)>=0,MAX('Monthly inputs'!K12)<=100000000,'Monthly inputs'!K12<=1000),IF(Setup!B5="hra",AND(COUNT('Monthly inputs'!L12)=1,MIN('Monthly inputs'!L12)>=0,MAX('Monthly inputs'!L12)<=100000000,'Monthly inputs'!L12<=1000),FALSE)))),IF(AND(OR(Setup!B5="increment",Setup!B5="da"),Setup!B8="Yes"),AND(COUNT('Monthly inputs'!M12)=1,MIN('Monthly inputs'!M12)>=0,MAX('Monthly inputs'!M12)<=100000000,'Monthly inputs'!M12>0),TRUE),IF(Setup!B7="jodhpur_gpf_arrear",AND(AND(COUNT('Monthly inputs'!AB12,'Monthly inputs'!AC12,'Monthly inputs'!AD12,'Monthly inputs'!AA12)=4,MIN('Monthly inputs'!AB12,'Monthly inputs'!AC12,'Monthly inputs'!AD12,'Monthly inputs'!AA12)>=0,MAX('Monthly inputs'!AB12,'Monthly inputs'!AC12,'Monthly inputs'!AD12,'Monthly inputs'!AA12)<=100000000,'Monthly inputs'!AB12=ROUND('Monthly inputs'!AB12,2),'Monthly inputs'!AC12=ROUND('Monthly inputs'!AC12,2),'Monthly inputs'!AD12=ROUND('Monthly inputs'!AD12,2),'Monthly inputs'!AA12=ROUND('Monthly inputs'!AA12,2)),OR('Monthly inputs'!X12="",'Monthly inputs'!X12=0),OR('Monthly inputs'!Y12="",'Monthly inputs'!Y12=0),OR('Monthly inputs'!Z12="",'Monthly inputs'!Z12=0)),IF(Setup!B7="jodhpur_classic",AND(AND(COUNT('Monthly inputs'!X12,'Monthly inputs'!Y12,'Monthly inputs'!Z12,'Monthly inputs'!AA12)=4,MIN('Monthly inputs'!X12,'Monthly inputs'!Y12,'Monthly inputs'!Z12,'Monthly inputs'!AA12)>=0,MAX('Monthly inputs'!X12,'Monthly inputs'!Y12,'Monthly inputs'!Z12,'Monthly inputs'!AA12)<=100000000,'Monthly inputs'!X12=ROUND('Monthly inputs'!X12,2),'Monthly inputs'!Y12=ROUND('Monthly inputs'!Y12,2),'Monthly inputs'!Z12=ROUND('Monthly inputs'!Z12,2),'Monthly inputs'!AA12=ROUND('Monthly inputs'!AA12,2)),OR('Monthly inputs'!AB12="",'Monthly inputs'!AB12=0),OR('Monthly inputs'!AC12="",'Monthly inputs'!AC12=0),OR('Monthly inputs'!AD12="",'Monthly inputs'!AD12=0)),FALSE))),"OK","INCOMPLETE"),"INCOMPLETE"))
A13: 2026-08 | B13: 46235 | C13: 46265 | D13: period | AQ13: =IF(COUNTA('Monthly inputs'!A13:AP13)=0,"UNUSED",IFERROR(IF(AND(AND(COUNT('Monthly inputs'!E13,'Monthly inputs'!F13,'Monthly inputs'!G13,'Monthly inputs'!H13,'Monthly inputs'!I13,'Monthly inputs'!S13,'Monthly inputs'!T13,'Monthly inputs'!U13,'Monthly inputs'!V13,'Monthly inputs'!W13)=10,MIN('Monthly inputs'!E13,'Monthly inputs'!F13,'Monthly inputs'!G13,'Monthly inputs'!H13,'Monthly inputs'!I13,'Monthly inputs'!S13,'Monthly inputs'!T13,'Monthly inputs'!U13,'Monthly inputs'!V13,'Monthly inputs'!W13)>=0,MAX('Monthly inputs'!E13,'Monthly inputs'!F13,'Monthly inputs'!G13,'Monthly inputs'!H13,'Monthly inputs'!I13,'Monthly inputs'!S13,'Monthly inputs'!T13,'Monthly inputs'!U13,'Monthly inputs'!V13,'Monthly inputs'!W13)<=100000000,'Monthly inputs'!E13=ROUND('Monthly inputs'!E13,2),'Monthly inputs'!F13=ROUND('Monthly inputs'!F13,2),'Monthly inputs'!G13=ROUND('Monthly inputs'!G13,2),'Monthly inputs'!H13=ROUND('Monthly inputs'!H13,2),'Monthly inputs'!I13=ROUND('Monthly inputs'!I13,2),'Monthly inputs'!S13=ROUND('Monthly inputs'!S13,2),'Monthly inputs'!T13=ROUND('Monthly inputs'!T13,2),'Monthly inputs'!U13=ROUND('Monthly inputs'!U13,2),'Monthly inputs'!V13=ROUND('Monthly inputs'!V13,2),'Monthly inputs'!W13=ROUND('Monthly inputs'!W13,2)),ISNUMBER('Monthly inputs'!B13),ISNUMBER('Monthly inputs'!C13),'Monthly inputs'!B13<='Monthly inputs'!C13,TEXT('Monthly inputs'!B13,"yyyy-mm")='Monthly inputs'!A13,TEXT('Monthly inputs'!C13,"yyyy-mm")='Monthly inputs'!A13,OR('Monthly inputs'!D13="period",'Monthly inputs'!D13="whole_month"),'Monthly inputs'!B13='Monthly inputs'!C12+1,'Monthly inputs'!A13<>'Monthly inputs'!A12,LEN(TRIM('Monthly inputs'!AE13))>0,LEN(TRIM('Monthly inputs'!AF13))>0,LEN(TRIM('Monthly inputs'!AG13))>0,LEN(TRIM('Monthly inputs'!AH13))>0,'Monthly inputs'!AI13="Yes",'Monthly inputs'!AJ13="Yes",LEN(TRIM(Setup!B3))>0,LEN(TRIM(Setup!B4))>0,OR(Setup!B6="rupee",Setup!B6="paise"),OR(Setup!B8="Yes",Setup!B8="No"),IF(Setup!B5="manual",AND(COUNT('Monthly inputs'!N13,'Monthly inputs'!O13,'Monthly inputs'!P13,'Monthly inputs'!Q13,'Monthly inputs'!R13)=5,MIN('Monthly inputs'!N13,'Monthly inputs'!O13,'Monthly inputs'!P13,'Monthly inputs'!Q13,'Monthly inputs'!R13)>=0,MAX('Monthly inputs'!N13,'Monthly inputs'!O13,'Monthly inputs'!P13,'Monthly inputs'!Q13,'Monthly inputs'!R13)<=100000000,'Monthly inputs'!N13=ROUND('Monthly inputs'!N13,2),'Monthly inputs'!O13=ROUND('Monthly inputs'!O13,2),'Monthly inputs'!P13=ROUND('Monthly inputs'!P13,2),'Monthly inputs'!Q13=ROUND('Monthly inputs'!Q13,2),'Monthly inputs'!R13=ROUND('Monthly inputs'!R13,2)),IF(Setup!B5="increment",AND(COUNT('Monthly inputs'!J13,'Monthly inputs'!K13,'Monthly inputs'!L13)=3,MIN('Monthly inputs'!J13,'Monthly inputs'!K13,'Monthly inputs'!L13)>=0,MAX('Monthly inputs'!J13,'Monthly inputs'!K13,'Monthly inputs'!L13)<=100000000,'Monthly inputs'!J13=ROUND('Monthly inputs'!J13,2),'Monthly inputs'!K13<=1000,'Monthly inputs'!L13<=1000),IF(Setup!B5="da",AND(COUNT('Monthly inputs'!K13)=1,MIN('Monthly inputs'!K13)>=0,MAX('Monthly inputs'!K13)<=100000000,'Monthly inputs'!K13<=1000),IF(Setup!B5="hra",AND(COUNT('Monthly inputs'!L13)=1,MIN('Monthly inputs'!L13)>=0,MAX('Monthly inputs'!L13)<=100000000,'Monthly inputs'!L13<=1000),FALSE)))),IF(AND(OR(Setup!B5="increment",Setup!B5="da"),Setup!B8="Yes"),AND(COUNT('Monthly inputs'!M13)=1,MIN('Monthly inputs'!M13)>=0,MAX('Monthly inputs'!M13)<=100000000,'Monthly inputs'!M13>0),TRUE),IF(Setup!B7="jodhpur_gpf_arrear",AND(AND(COUNT('Monthly inputs'!AB13,'Monthly inputs'!AC13,'Monthly inputs'!AD13,'Monthly inputs'!AA13)=4,MIN('Monthly inputs'!AB13,'Monthly inputs'!AC13,'Monthly inputs'!AD13,'Monthly inputs'!AA13)>=0,MAX('Monthly inputs'!AB13,'Monthly inputs'!AC13,'Monthly inputs'!AD13,'Monthly inputs'!AA13)<=100000000,'Monthly inputs'!AB13=ROUND('Monthly inputs'!AB13,2),'Monthly inputs'!AC13=ROUND('Monthly inputs'!AC13,2),'Monthly inputs'!AD13=ROUND('Monthly inputs'!AD13,2),'Monthly inputs'!AA13=ROUND('Monthly inputs'!AA13,2)),OR('Monthly inputs'!X13="",'Monthly inputs'!X13=0),OR('Monthly inputs'!Y13="",'Monthly inputs'!Y13=0),OR('Monthly inputs'!Z13="",'Monthly inputs'!Z13=0)),IF(Setup!B7="jodhpur_classic",AND(AND(COUNT('Monthly inputs'!X13,'Monthly inputs'!Y13,'Monthly inputs'!Z13,'Monthly inputs'!AA13)=4,MIN('Monthly inputs'!X13,'Monthly inputs'!Y13,'Monthly inputs'!Z13,'Monthly inputs'!AA13)>=0,MAX('Monthly inputs'!X13,'Monthly inputs'!Y13,'Monthly inputs'!Z13,'Monthly inputs'!AA13)<=100000000,'Monthly inputs'!X13=ROUND('Monthly inputs'!X13,2),'Monthly inputs'!Y13=ROUND('Monthly inputs'!Y13,2),'Monthly inputs'!Z13=ROUND('Monthly inputs'!Z13,2),'Monthly inputs'!AA13=ROUND('Monthly inputs'!AA13,2)),OR('Monthly inputs'!AB13="",'Monthly inputs'!AB13=0),OR('Monthly inputs'!AC13="",'Monthly inputs'!AC13=0),OR('Monthly inputs'!AD13="",'Monthly inputs'!AD13=0)),FALSE))),"OK","INCOMPLETE"),"INCOMPLETE"))
A14: 2026-09 | B14: 46266 | C14: 46295 | D14: period | AQ14: =IF(COUNTA('Monthly inputs'!A14:AP14)=0,"UNUSED",IFERROR(IF(AND(AND(COUNT('Monthly inputs'!E14,'Monthly inputs'!F14,'Monthly inputs'!G14,'Monthly inputs'!H14,'Monthly inputs'!I14,'Monthly inputs'!S14,'Monthly inputs'!T14,'Monthly inputs'!U14,'Monthly inputs'!V14,'Monthly inputs'!W14)=10,MIN('Monthly inputs'!E14,'Monthly inputs'!F14,'Monthly inputs'!G14,'Monthly inputs'!H14,'Monthly inputs'!I14,'Monthly inputs'!S14,'Monthly inputs'!T14,'Monthly inputs'!U14,'Monthly inputs'!V14,'Monthly inputs'!W14)>=0,MAX('Monthly inputs'!E14,'Monthly inputs'!F14,'Monthly inputs'!G14,'Monthly inputs'!H14,'Monthly inputs'!I14,'Monthly inputs'!S14,'Monthly inputs'!T14,'Monthly inputs'!U14,'Monthly inputs'!V14,'Monthly inputs'!W14)<=100000000,'Monthly inputs'!E14=ROUND('Monthly inputs'!E14,2),'Monthly inputs'!F14=ROUND('Monthly inputs'!F14,2),'Monthly inputs'!G14=ROUND('Monthly inputs'!G14,2),'Monthly inputs'!H14=ROUND('Monthly inputs'!H14,2),'Monthly inputs'!I14=ROUND('Monthly inputs'!I14,2),'Monthly inputs'!S14=ROUND('Monthly inputs'!S14,2),'Monthly inputs'!T14=ROUND('Monthly inputs'!T14,2),'Monthly inputs'!U14=ROUND('Monthly inputs'!U14,2),'Monthly inputs'!V14=ROUND('Monthly inputs'!V14,2),'Monthly inputs'!W14=ROUND('Monthly inputs'!W14,2)),ISNUMBER('Monthly inputs'!B14),ISNUMBER('Monthly inputs'!C14),'Monthly inputs'!B14<='Monthly inputs'!C14,TEXT('Monthly inputs'!B14,"yyyy-mm")='Monthly inputs'!A14,TEXT('Monthly inputs'!C14,"yyyy-mm")='Monthly inputs'!A14,OR('Monthly inputs'!D14="period",'Monthly inputs'!D14="whole_month"),'Monthly inputs'!B14='Monthly inputs'!C13+1,'Monthly inputs'!A14<>'Monthly inputs'!A13,LEN(TRIM('Monthly inputs'!AE14))>0,LEN(TRIM('Monthly inputs'!AF14))>0,LEN(TRIM('Monthly inputs'!AG14))>0,LEN(TRIM('Monthly inputs'!AH14))>0,'Monthly inputs'!AI14="Yes",'Monthly inputs'!AJ14="Yes",LEN(TRIM(Setup!B3))>0,LEN(TRIM(Setup!B4))>0,OR(Setup!B6="rupee",Setup!B6="paise"),OR(Setup!B8="Yes",Setup!B8="No"),IF(Setup!B5="manual",AND(COUNT('Monthly inputs'!N14,'Monthly inputs'!O14,'Monthly inputs'!P14,'Monthly inputs'!Q14,'Monthly inputs'!R14)=5,MIN('Monthly inputs'!N14,'Monthly inputs'!O14,'Monthly inputs'!P14,'Monthly inputs'!Q14,'Monthly inputs'!R14)>=0,MAX('Monthly inputs'!N14,'Monthly inputs'!O14,'Monthly inputs'!P14,'Monthly inputs'!Q14,'Monthly inputs'!R14)<=100000000,'Monthly inputs'!N14=ROUND('Monthly inputs'!N14,2),'Monthly inputs'!O14=ROUND('Monthly inputs'!O14,2),'Monthly inputs'!P14=ROUND('Monthly inputs'!P14,2),'Monthly inputs'!Q14=ROUND('Monthly inputs'!Q14,2),'Monthly inputs'!R14=ROUND('Monthly inputs'!R14,2)),IF(Setup!B5="increment",AND(COUNT('Monthly inputs'!J14,'Monthly inputs'!K14,'Monthly inputs'!L14)=3,MIN('Monthly inputs'!J14,'Monthly inputs'!K14,'Monthly inputs'!L14)>=0,MAX('Monthly inputs'!J14,'Monthly inputs'!K14,'Monthly inputs'!L14)<=100000000,'Monthly inputs'!J14=ROUND('Monthly inputs'!J14,2),'Monthly inputs'!K14<=1000,'Monthly inputs'!L14<=1000),IF(Setup!B5="da",AND(COUNT('Monthly inputs'!K14)=1,MIN('Monthly inputs'!K14)>=0,MAX('Monthly inputs'!K14)<=100000000,'Monthly inputs'!K14<=1000),IF(Setup!B5="hra",AND(COUNT('Monthly inputs'!L14)=1,MIN('Monthly inputs'!L14)>=0,MAX('Monthly inputs'!L14)<=100000000,'Monthly inputs'!L14<=1000),FALSE)))),IF(AND(OR(Setup!B5="increment",Setup!B5="da"),Setup!B8="Yes"),AND(COUNT('Monthly inputs'!M14)=1,MIN('Monthly inputs'!M14)>=0,MAX('Monthly inputs'!M14)<=100000000,'Monthly inputs'!M14>0),TRUE),IF(Setup!B7="jodhpur_gpf_arrear",AND(AND(COUNT('Monthly inputs'!AB14,'Monthly inputs'!AC14,'Monthly inputs'!AD14,'Monthly inputs'!AA14)=4,MIN('Monthly inputs'!AB14,'Monthly inputs'!AC14,'Monthly inputs'!AD14,'Monthly inputs'!AA14)>=0,MAX('Monthly inputs'!AB14,'Monthly inputs'!AC14,'Monthly inputs'!AD14,'Monthly inputs'!AA14)<=100000000,'Monthly inputs'!AB14=ROUND('Monthly inputs'!AB14,2),'Monthly inputs'!AC14=ROUND('Monthly inputs'!AC14,2),'Monthly inputs'!AD14=ROUND('Monthly inputs'!AD14,2),'Monthly inputs'!AA14=ROUND('Monthly inputs'!AA14,2)),OR('Monthly inputs'!X14="",'Monthly inputs'!X14=0),OR('Monthly inputs'!Y14="",'Monthly inputs'!Y14=0),OR('Monthly inputs'!Z14="",'Monthly inputs'!Z14=0)),IF(Setup!B7="jodhpur_classic",AND(AND(COUNT('Monthly inputs'!X14,'Monthly inputs'!Y14,'Monthly inputs'!Z14,'Monthly inputs'!AA14)=4,MIN('Monthly inputs'!X14,'Monthly inputs'!Y14,'Monthly inputs'!Z14,'Monthly inputs'!AA14)>=0,MAX('Monthly inputs'!X14,'Monthly inputs'!Y14,'Monthly inputs'!Z14,'Monthly inputs'!AA14)<=100000000,'Monthly inputs'!X14=ROUND('Monthly inputs'!X14,2),'Monthly inputs'!Y14=ROUND('Monthly inputs'!Y14,2),'Monthly inputs'!Z14=ROUND('Monthly inputs'!Z14,2),'Monthly inputs'!AA14=ROUND('Monthly inputs'!AA14,2)),OR('Monthly inputs'!AB14="",'Monthly inputs'!AB14=0),OR('Monthly inputs'!AC14="",'Monthly inputs'!AC14=0),OR('Monthly inputs'!AD14="",'Monthly inputs'!AD14=0)),FALSE))),"OK","INCOMPLETE"),"INCOMPLETE"))
A15: 2026-10 | B15: 46296 | C15: 46326 | D15: period | AQ15: =IF(COUNTA('Monthly inputs'!A15:AP15)=0,"UNUSED",IFERROR(IF(AND(AND(COUNT('Monthly inputs'!E15,'Monthly inputs'!F15,'Monthly inputs'!G15,'Monthly inputs'!H15,'Monthly inputs'!I15,'Monthly inputs'!S15,'Monthly inputs'!T15,'Monthly inputs'!U15,'Monthly inputs'!V15,'Monthly inputs'!W15)=10,MIN('Monthly inputs'!E15,'Monthly inputs'!F15,'Monthly inputs'!G15,'Monthly inputs'!H15,'Monthly inputs'!I15,'Monthly inputs'!S15,'Monthly inputs'!T15,'Monthly inputs'!U15,'Monthly inputs'!V15,'Monthly inputs'!W15)>=0,MAX('Monthly inputs'!E15,'Monthly inputs'!F15,'Monthly inputs'!G15,'Monthly inputs'!H15,'Monthly inputs'!I15,'Monthly inputs'!S15,'Monthly inputs'!T15,'Monthly inputs'!U15,'Monthly inputs'!V15,'Monthly inputs'!W15)<=100000000,'Monthly inputs'!E15=ROUND('Monthly inputs'!E15,2),'Monthly inputs'!F15=ROUND('Monthly inputs'!F15,2),'Monthly inputs'!G15=ROUND('Monthly inputs'!G15,2),'Monthly inputs'!H15=ROUND('Monthly inputs'!H15,2),'Monthly inputs'!I15=ROUND('Monthly inputs'!I15,2),'Monthly inputs'!S15=ROUND('Monthly inputs'!S15,2),'Monthly inputs'!T15=ROUND('Monthly inputs'!T15,2),'Monthly inputs'!U15=ROUND('Monthly inputs'!U15,2),'Monthly inputs'!V15=ROUND('Monthly inputs'!V15,2),'Monthly inputs'!W15=ROUND('Monthly inputs'!W15,2)),ISNUMBER('Monthly inputs'!B15),ISNUMBER('Monthly inputs'!C15),'Monthly inputs'!B15<='Monthly inputs'!C15,TEXT('Monthly inputs'!B15,"yyyy-mm")='Monthly inputs'!A15,TEXT('Monthly inputs'!C15,"yyyy-mm")='Monthly inputs'!A15,OR('Monthly inputs'!D15="period",'Monthly inputs'!D15="whole_month"),'Monthly inputs'!B15='Monthly inputs'!C14+1,'Monthly inputs'!A15<>'Monthly inputs'!A14,LEN(TRIM('Monthly inputs'!AE15))>0,LEN(TRIM('Monthly inputs'!AF15))>0,LEN(TRIM('Monthly inputs'!AG15))>0,LEN(TRIM('Monthly inputs'!AH15))>0,'Monthly inputs'!AI15="Yes",'Monthly inputs'!AJ15="Yes",LEN(TRIM(Setup!B3))>0,LEN(TRIM(Setup!B4))>0,OR(Setup!B6="rupee",Setup!B6="paise"),OR(Setup!B8="Yes",Setup!B8="No"),IF(Setup!B5="manual",AND(COUNT('Monthly inputs'!N15,'Monthly inputs'!O15,'Monthly inputs'!P15,'Monthly inputs'!Q15,'Monthly inputs'!R15)=5,MIN('Monthly inputs'!N15,'Monthly inputs'!O15,'Monthly inputs'!P15,'Monthly inputs'!Q15,'Monthly inputs'!R15)>=0,MAX('Monthly inputs'!N15,'Monthly inputs'!O15,'Monthly inputs'!P15,'Monthly inputs'!Q15,'Monthly inputs'!R15)<=100000000,'Monthly inputs'!N15=ROUND('Monthly inputs'!N15,2),'Monthly inputs'!O15=ROUND('Monthly inputs'!O15,2),'Monthly inputs'!P15=ROUND('Monthly inputs'!P15,2),'Monthly inputs'!Q15=ROUND('Monthly inputs'!Q15,2),'Monthly inputs'!R15=ROUND('Monthly inputs'!R15,2)),IF(Setup!B5="increment",AND(COUNT('Monthly inputs'!J15,'Monthly inputs'!K15,'Monthly inputs'!L15)=3,MIN('Monthly inputs'!J15,'Monthly inputs'!K15,'Monthly inputs'!L15)>=0,MAX('Monthly inputs'!J15,'Monthly inputs'!K15,'Monthly inputs'!L15)<=100000000,'Monthly inputs'!J15=ROUND('Monthly inputs'!J15,2),'Monthly inputs'!K15<=1000,'Monthly inputs'!L15<=1000),IF(Setup!B5="da",AND(COUNT('Monthly inputs'!K15)=1,MIN('Monthly inputs'!K15)>=0,MAX('Monthly inputs'!K15)<=100000000,'Monthly inputs'!K15<=1000),IF(Setup!B5="hra",AND(COUNT('Monthly inputs'!L15)=1,MIN('Monthly inputs'!L15)>=0,MAX('Monthly inputs'!L15)<=100000000,'Monthly inputs'!L15<=1000),FALSE)))),IF(AND(OR(Setup!B5="increment",Setup!B5="da"),Setup!B8="Yes"),AND(COUNT('Monthly inputs'!M15)=1,MIN('Monthly inputs'!M15)>=0,MAX('Monthly inputs'!M15)<=100000000,'Monthly inputs'!M15>0),TRUE),IF(Setup!B7="jodhpur_gpf_arrear",AND(AND(COUNT('Monthly inputs'!AB15,'Monthly inputs'!AC15,'Monthly inputs'!AD15,'Monthly inputs'!AA15)=4,MIN('Monthly inputs'!AB15,'Monthly inputs'!AC15,'Monthly inputs'!AD15,'Monthly inputs'!AA15)>=0,MAX('Monthly inputs'!AB15,'Monthly inputs'!AC15,'Monthly inputs'!AD15,'Monthly inputs'!AA15)<=100000000,'Monthly inputs'!AB15=ROUND('Monthly inputs'!AB15,2),'Monthly inputs'!AC15=ROUND('Monthly inputs'!AC15,2),'Monthly inputs'!AD15=ROUND('Monthly inputs'!AD15,2),'Monthly inputs'!AA15=ROUND('Monthly inputs'!AA15,2)),OR('Monthly inputs'!X15="",'Monthly inputs'!X15=0),OR('Monthly inputs'!Y15="",'Monthly inputs'!Y15=0),OR('Monthly inputs'!Z15="",'Monthly inputs'!Z15=0)),IF(Setup!B7="jodhpur_classic",AND(AND(COUNT('Monthly inputs'!X15,'Monthly inputs'!Y15,'Monthly inputs'!Z15,'Monthly inputs'!AA15)=4,MIN('Monthly inputs'!X15,'Monthly inputs'!Y15,'Monthly inputs'!Z15,'Monthly inputs'!AA15)>=0,MAX('Monthly inputs'!X15,'Monthly inputs'!Y15,'Monthly inputs'!Z15,'Monthly inputs'!AA15)<=100000000,'Monthly inputs'!X15=ROUND('Monthly inputs'!X15,2),'Monthly inputs'!Y15=ROUND('Monthly inputs'!Y15,2),'Monthly inputs'!Z15=ROUND('Monthly inputs'!Z15,2),'Monthly inputs'!AA15=ROUND('Monthly inputs'!AA15,2)),OR('Monthly inputs'!AB15="",'Monthly inputs'!AB15=0),OR('Monthly inputs'!AC15="",'Monthly inputs'!AC15=0),OR('Monthly inputs'!AD15="",'Monthly inputs'!AD15=0)),FALSE))),"OK","INCOMPLETE"),"INCOMPLETE"))
A16: 2026-11 | B16: 46327 | C16: 46356 | D16: period | AQ16: =IF(COUNTA('Monthly inputs'!A16:AP16)=0,"UNUSED",IFERROR(IF(AND(AND(COUNT('Monthly inputs'!E16,'Monthly inputs'!F16,'Monthly inputs'!G16,'Monthly inputs'!H16,'Monthly inputs'!I16,'Monthly inputs'!S16,'Monthly inputs'!T16,'Monthly inputs'!U16,'Monthly inputs'!V16,'Monthly inputs'!W16)=10,MIN('Monthly inputs'!E16,'Monthly inputs'!F16,'Monthly inputs'!G16,'Monthly inputs'!H16,'Monthly inputs'!I16,'Monthly inputs'!S16,'Monthly inputs'!T16,'Monthly inputs'!U16,'Monthly inputs'!V16,'Monthly inputs'!W16)>=0,MAX('Monthly inputs'!E16,'Monthly inputs'!F16,'Monthly inputs'!G16,'Monthly inputs'!H16,'Monthly inputs'!I16,'Monthly inputs'!S16,'Monthly inputs'!T16,'Monthly inputs'!U16,'Monthly inputs'!V16,'Monthly inputs'!W16)<=100000000,'Monthly inputs'!E16=ROUND('Monthly inputs'!E16,2),'Monthly inputs'!F16=ROUND('Monthly inputs'!F16,2),'Monthly inputs'!G16=ROUND('Monthly inputs'!G16,2),'Monthly inputs'!H16=ROUND('Monthly inputs'!H16,2),'Monthly inputs'!I16=ROUND('Monthly inputs'!I16,2),'Monthly inputs'!S16=ROUND('Monthly inputs'!S16,2),'Monthly inputs'!T16=ROUND('Monthly inputs'!T16,2),'Monthly inputs'!U16=ROUND('Monthly inputs'!U16,2),'Monthly inputs'!V16=ROUND('Monthly inputs'!V16,2),'Monthly inputs'!W16=ROUND('Monthly inputs'!W16,2)),ISNUMBER('Monthly inputs'!B16),ISNUMBER('Monthly inputs'!C16),'Monthly inputs'!B16<='Monthly inputs'!C16,TEXT('Monthly inputs'!B16,"yyyy-mm")='Monthly inputs'!A16,TEXT('Monthly inputs'!C16,"yyyy-mm")='Monthly inputs'!A16,OR('Monthly inputs'!D16="period",'Monthly inputs'!D16="whole_month"),'Monthly inputs'!B16='Monthly inputs'!C15+1,'Monthly inputs'!A16<>'Monthly inputs'!A15,LEN(TRIM('Monthly inputs'!AE16))>0,LEN(TRIM('Monthly inputs'!AF16))>0,LEN(TRIM('Monthly inputs'!AG16))>0,LEN(TRIM('Monthly inputs'!AH16))>0,'Monthly inputs'!AI16="Yes",'Monthly inputs'!AJ16="Yes",LEN(TRIM(Setup!B3))>0,LEN(TRIM(Setup!B4))>0,OR(Setup!B6="rupee",Setup!B6="paise"),OR(Setup!B8="Yes",Setup!B8="No"),IF(Setup!B5="manual",AND(COUNT('Monthly inputs'!N16,'Monthly inputs'!O16,'Monthly inputs'!P16,'Monthly inputs'!Q16,'Monthly inputs'!R16)=5,MIN('Monthly inputs'!N16,'Monthly inputs'!O16,'Monthly inputs'!P16,'Monthly inputs'!Q16,'Monthly inputs'!R16)>=0,MAX('Monthly inputs'!N16,'Monthly inputs'!O16,'Monthly inputs'!P16,'Monthly inputs'!Q16,'Monthly inputs'!R16)<=100000000,'Monthly inputs'!N16=ROUND('Monthly inputs'!N16,2),'Monthly inputs'!O16=ROUND('Monthly inputs'!O16,2),'Monthly inputs'!P16=ROUND('Monthly inputs'!P16,2),'Monthly inputs'!Q16=ROUND('Monthly inputs'!Q16,2),'Monthly inputs'!R16=ROUND('Monthly inputs'!R16,2)),IF(Setup!B5="increment",AND(COUNT('Monthly inputs'!J16,'Monthly inputs'!K16,'Monthly inputs'!L16)=3,MIN('Monthly inputs'!J16,'Monthly inputs'!K16,'Monthly inputs'!L16)>=0,MAX('Monthly inputs'!J16,'Monthly inputs'!K16,'Monthly inputs'!L16)<=100000000,'Monthly inputs'!J16=ROUND('Monthly inputs'!J16,2),'Monthly inputs'!K16<=1000,'Monthly inputs'!L16<=1000),IF(Setup!B5="da",AND(COUNT('Monthly inputs'!K16)=1,MIN('Monthly inputs'!K16)>=0,MAX('Monthly inputs'!K16)<=100000000,'Monthly inputs'!K16<=1000),IF(Setup!B5="hra",AND(COUNT('Monthly inputs'!L16)=1,MIN('Monthly inputs'!L16)>=0,MAX('Monthly inputs'!L16)<=100000000,'Monthly inputs'!L16<=1000),FALSE)))),IF(AND(OR(Setup!B5="increment",Setup!B5="da"),Setup!B8="Yes"),AND(COUNT('Monthly inputs'!M16)=1,MIN('Monthly inputs'!M16)>=0,MAX('Monthly inputs'!M16)<=100000000,'Monthly inputs'!M16>0),TRUE),IF(Setup!B7="jodhpur_gpf_arrear",AND(AND(COUNT('Monthly inputs'!AB16,'Monthly inputs'!AC16,'Monthly inputs'!AD16,'Monthly inputs'!AA16)=4,MIN('Monthly inputs'!AB16,'Monthly inputs'!AC16,'Monthly inputs'!AD16,'Monthly inputs'!AA16)>=0,MAX('Monthly inputs'!AB16,'Monthly inputs'!AC16,'Monthly inputs'!AD16,'Monthly inputs'!AA16)<=100000000,'Monthly inputs'!AB16=ROUND('Monthly inputs'!AB16,2),'Monthly inputs'!AC16=ROUND('Monthly inputs'!AC16,2),'Monthly inputs'!AD16=ROUND('Monthly inputs'!AD16,2),'Monthly inputs'!AA16=ROUND('Monthly inputs'!AA16,2)),OR('Monthly inputs'!X16="",'Monthly inputs'!X16=0),OR('Monthly inputs'!Y16="",'Monthly inputs'!Y16=0),OR('Monthly inputs'!Z16="",'Monthly inputs'!Z16=0)),IF(Setup!B7="jodhpur_classic",AND(AND(COUNT('Monthly inputs'!X16,'Monthly inputs'!Y16,'Monthly inputs'!Z16,'Monthly inputs'!AA16)=4,MIN('Monthly inputs'!X16,'Monthly inputs'!Y16,'Monthly inputs'!Z16,'Monthly inputs'!AA16)>=0,MAX('Monthly inputs'!X16,'Monthly inputs'!Y16,'Monthly inputs'!Z16,'Monthly inputs'!AA16)<=100000000,'Monthly inputs'!X16=ROUND('Monthly inputs'!X16,2),'Monthly inputs'!Y16=ROUND('Monthly inputs'!Y16,2),'Monthly inputs'!Z16=ROUND('Monthly inputs'!Z16,2),'Monthly inputs'!AA16=ROUND('Monthly inputs'!AA16,2)),OR('Monthly inputs'!AB16="",'Monthly inputs'!AB16=0),OR('Monthly inputs'!AC16="",'Monthly inputs'!AC16=0),OR('Monthly inputs'!AD16="",'Monthly inputs'!AD16=0)),FALSE))),"OK","INCOMPLETE"),"INCOMPLETE"))
A17: 2026-12 | B17: 46357 | C17: 46387 | D17: period | AQ17: =IF(COUNTA('Monthly inputs'!A17:AP17)=0,"UNUSED",IFERROR(IF(AND(AND(COUNT('Monthly inputs'!E17,'Monthly inputs'!F17,'Monthly inputs'!G17,'Monthly inputs'!H17,'Monthly inputs'!I17,'Monthly inputs'!S17,'Monthly inputs'!T17,'Monthly inputs'!U17,'Monthly inputs'!V17,'Monthly inputs'!W17)=10,MIN('Monthly inputs'!E17,'Monthly inputs'!F17,'Monthly inputs'!G17,'Monthly inputs'!H17,'Monthly inputs'!I17,'Monthly inputs'!S17,'Monthly inputs'!T17,'Monthly inputs'!U17,'Monthly inputs'!V17,'Monthly inputs'!W17)>=0,MAX('Monthly inputs'!E17,'Monthly inputs'!F17,'Monthly inputs'!G17,'Monthly inputs'!H17,'Monthly inputs'!I17,'Monthly inputs'!S17,'Monthly inputs'!T17,'Monthly inputs'!U17,'Monthly inputs'!V17,'Monthly inputs'!W17)<=100000000,'Monthly inputs'!E17=ROUND('Monthly inputs'!E17,2),'Monthly inputs'!F17=ROUND('Monthly inputs'!F17,2),'Monthly inputs'!G17=ROUND('Monthly inputs'!G17,2),'Monthly inputs'!H17=ROUND('Monthly inputs'!H17,2),'Monthly inputs'!I17=ROUND('Monthly inputs'!I17,2),'Monthly inputs'!S17=ROUND('Monthly inputs'!S17,2),'Monthly inputs'!T17=ROUND('Monthly inputs'!T17,2),'Monthly inputs'!U17=ROUND('Monthly inputs'!U17,2),'Monthly inputs'!V17=ROUND('Monthly inputs'!V17,2),'Monthly inputs'!W17=ROUND('Monthly inputs'!W17,2)),ISNUMBER('Monthly inputs'!B17),ISNUMBER('Monthly inputs'!C17),'Monthly inputs'!B17<='Monthly inputs'!C17,TEXT('Monthly inputs'!B17,"yyyy-mm")='Monthly inputs'!A17,TEXT('Monthly inputs'!C17,"yyyy-mm")='Monthly inputs'!A17,OR('Monthly inputs'!D17="period",'Monthly inputs'!D17="whole_month"),'Monthly inputs'!B17='Monthly inputs'!C16+1,'Monthly inputs'!A17<>'Monthly inputs'!A16,LEN(TRIM('Monthly inputs'!AE17))>0,LEN(TRIM('Monthly inputs'!AF17))>0,LEN(TRIM('Monthly inputs'!AG17))>0,LEN(TRIM('Monthly inputs'!AH17))>0,'Monthly inputs'!AI17="Yes",'Monthly inputs'!AJ17="Yes",LEN(TRIM(Setup!B3))>0,LEN(TRIM(Setup!B4))>0,OR(Setup!B6="rupee",Setup!B6="paise"),OR(Setup!B8="Yes",Setup!B8="No"),IF(Setup!B5="manual",AND(COUNT('Monthly inputs'!N17,'Monthly inputs'!O17,'Monthly inputs'!P17,'Monthly inputs'!Q17,'Monthly inputs'!R17)=5,MIN('Monthly inputs'!N17,'Monthly inputs'!O17,'Monthly inputs'!P17,'Monthly inputs'!Q17,'Monthly inputs'!R17)>=0,MAX('Monthly inputs'!N17,'Monthly inputs'!O17,'Monthly inputs'!P17,'Monthly inputs'!Q17,'Monthly inputs'!R17)<=100000000,'Monthly inputs'!N17=ROUND('Monthly inputs'!N17,2),'Monthly inputs'!O17=ROUND('Monthly inputs'!O17,2),'Monthly inputs'!P17=ROUND('Monthly inputs'!P17,2),'Monthly inputs'!Q17=ROUND('Monthly inputs'!Q17,2),'Monthly inputs'!R17=ROUND('Monthly inputs'!R17,2)),IF(Setup!B5="increment",AND(COUNT('Monthly inputs'!J17,'Monthly inputs'!K17,'Monthly inputs'!L17)=3,MIN('Monthly inputs'!J17,'Monthly inputs'!K17,'Monthly inputs'!L17)>=0,MAX('Monthly inputs'!J17,'Monthly inputs'!K17,'Monthly inputs'!L17)<=100000000,'Monthly inputs'!J17=ROUND('Monthly inputs'!J17,2),'Monthly inputs'!K17<=1000,'Monthly inputs'!L17<=1000),IF(Setup!B5="da",AND(COUNT('Monthly inputs'!K17)=1,MIN('Monthly inputs'!K17)>=0,MAX('Monthly inputs'!K17)<=100000000,'Monthly inputs'!K17<=1000),IF(Setup!B5="hra",AND(COUNT('Monthly inputs'!L17)=1,MIN('Monthly inputs'!L17)>=0,MAX('Monthly inputs'!L17)<=100000000,'Monthly inputs'!L17<=1000),FALSE)))),IF(AND(OR(Setup!B5="increment",Setup!B5="da"),Setup!B8="Yes"),AND(COUNT('Monthly inputs'!M17)=1,MIN('Monthly inputs'!M17)>=0,MAX('Monthly inputs'!M17)<=100000000,'Monthly inputs'!M17>0),TRUE),IF(Setup!B7="jodhpur_gpf_arrear",AND(AND(COUNT('Monthly inputs'!AB17,'Monthly inputs'!AC17,'Monthly inputs'!AD17,'Monthly inputs'!AA17)=4,MIN('Monthly inputs'!AB17,'Monthly inputs'!AC17,'Monthly inputs'!AD17,'Monthly inputs'!AA17)>=0,MAX('Monthly inputs'!AB17,'Monthly inputs'!AC17,'Monthly inputs'!AD17,'Monthly inputs'!AA17)<=100000000,'Monthly inputs'!AB17=ROUND('Monthly inputs'!AB17,2),'Monthly inputs'!AC17=ROUND('Monthly inputs'!AC17,2),'Monthly inputs'!AD17=ROUND('Monthly inputs'!AD17,2),'Monthly inputs'!AA17=ROUND('Monthly inputs'!AA17,2)),OR('Monthly inputs'!X17="",'Monthly inputs'!X17=0),OR('Monthly inputs'!Y17="",'Monthly inputs'!Y17=0),OR('Monthly inputs'!Z17="",'Monthly inputs'!Z17=0)),IF(Setup!B7="jodhpur_classic",AND(AND(COUNT('Monthly inputs'!X17,'Monthly inputs'!Y17,'Monthly inputs'!Z17,'Monthly inputs'!AA17)=4,MIN('Monthly inputs'!X17,'Monthly inputs'!Y17,'Monthly inputs'!Z17,'Monthly inputs'!AA17)>=0,MAX('Monthly inputs'!X17,'Monthly inputs'!Y17,'Monthly inputs'!Z17,'Monthly inputs'!AA17)<=100000000,'Monthly inputs'!X17=ROUND('Monthly inputs'!X17,2),'Monthly inputs'!Y17=ROUND('Monthly inputs'!Y17,2),'Monthly inputs'!Z17=ROUND('Monthly inputs'!Z17,2),'Monthly inputs'!AA17=ROUND('Monthly inputs'!AA17,2)),OR('Monthly inputs'!AB17="",'Monthly inputs'!AB17=0),OR('Monthly inputs'!AC17="",'Monthly inputs'!AC17=0),OR('Monthly inputs'!AD17="",'Monthly inputs'!AD17=0)),FALSE))),"OK","INCOMPLETE"),"INCOMPLETE"))

Sheet Due drawn statement
A1: OFFICE OF THE POLICE COMMISSIONER JODHPUR
A2: ="NAME = " & Setup!B3 | P2: ="EMP. ID = " & Setup!B4
